<robot name="final_robot">

  <link name="base_link">
    <visual>
      <geometry>
        <box size="0.16 0.16 0.01" />
      </geometry>
      <origin xyz="0 0 0" rpy="0 0 0" />
    </visual>
    <collision>
      <geometry>
        <box size="0.16 0.16 0.01" />
      </geometry>
    </collision>
  </link>
  <link name="base_foot">
    <visual>
      <origin xyz="0 0 0" rpy="0 0 0" />
      <geometry>
        <box size="0.001 0.001 0.001" />
      </geometry>
    </visual>
  </link>
  <joint name="base_link_joint" type="fixed">
    <origin xyz="0 0 0.04" rpy="0 0 0" />
    <parent link="base_foot"/>
    <child link="base_link"/>
  </joint>
  <link name="left_wheel">
    <visual>
      <origin xyz="0 0 0" rpy="1.57075 0 0"/>
      <geometry>
        <cylinder radius="0.035" length="0.005"/>
      </geometry>
    </visual>
    <collision>
      <origin xyz="0 0 0" rpy="1.57075 0 0"/>
      <geometry>
        <cylinder radius="0.035" length="0.005"/>
      </geometry>
    </collision>
  </link>
  <joint name="left_wheel_joint" type="continuous">
    <axis xyz="0 1 0" rpy="0 0 0" />
    <parent link="base_link"/>
    <child link="left_wheel"/>
    <origin xyz="0.08 0.087 -0.005" rpy="0 0 0"/>
  </joint>
  
  <link name="right_wheel">
    <visual>
      <origin xyz="0 0 0" rpy="1.57075 0 0"/>
      <geometry>
        <cylinder radius="0.035" length="0.005"/>
      </geometry>
    </visual>
    <collision>
      <origin xyz="0 0 0" rpy="1.57075 0 0"/>
      <geometry>
        <cylinder radius="0.035" length="0.005"/>
      </geometry>
    </collision>
  </link>
  <joint name="right_wheel_joint" type="continuous">
    <axis xyz="0 1 0" rpy="0 0 0" />
    <parent link="base_link"/>
    <child link="right_wheel"/>
    <origin xyz="0.08 -0.087 -0.005" rpy="0 0 0"/>
  </joint>  
  
  <link name="front_wheel">
    <visual>
      <origin xyz="0 0 0" rpy="0 0 0"/>
      <geometry>
        <sphere radius="0.0175"/>
      </geometry>
    </visual>
    <collision>
      <origin xyz="0 0 0" rpy="0 0 0"/>
      <geometry>
        <sphere radius="0.0175"/>
      </geometry>   
    </collision>
  </link>
  
  <joint name="front_wheel_joint" type="continuous">
    <axis xyz="0 1 0" rpy="0 0 0" />
    <parent link="base_link"/>
    <child link="front_wheel"/>
    <origin xyz="-0.052 0 -0.0225" rpy="0 0 0"/>
  </joint>  
</robot>
